Workbook

Sheet Program
A1: 16-Week Autoregulated Hangboard Program — Transmutation Entry
A2: Skips accumulation — goes straight to Transmutation I given established hangboard base. Three transmutation blocks with rising intensity, separated by deload + benchmark weeks.
A4: Cycle Parameters
A5: Start date | C5: Mon May 11, 2026
A6: End date | C6: Sun Aug 30, 2026 (~16 weeks)
A7: Starting benchmark | C7: +25 kg on 20mm half crimp, 5s, 2-arm
A8: Nutrition | C8: Maintenance (cut complete)
A9: Weekly structure | C9: From W4: Tue OI primer + limit board, Thu volume yielding (5s), Sat heavy yielding = 3 finger sessions/week. Heavy = 5s in Trans I–II; 3s max singles in Peak (W11–14). (W1–W3 ran Tue heavy + Thu volume + Sat/Sun OI.)
A10: Deload cadence | C10: Every 5 weeks: W5, W10, W15 (each with benchmark test)
A11: Benchmark tests | C11: W5 (post-Trans I), W10 (post-Trans II), W15 (post-Peak), W16 (final, in Realization)
A12: Target end-of-cycle | C12: +33–40 kg (conservative ↔ optimistic). 8A path: ~+45–50 kg.
A14: Macro Schedule
A15: Wk | B15: Dates | C15: Block | D15: Heavy yielding (Sat, W4+) | E15: Thursday — Volume | F15: OI (Tue primer, W4+)
A16: W1 | B16: May 11 – May 17 | C16: Transmutation I 1/4 | D16: Top @8.5 autoreg (target ~+24 kg), 3 BO 92–95% with fatigue stop | E16: 82–85% of Tue, 4–5 sets @7–8 | F16: 2× standard
A17: W2 | B17: May 18 – May 24 | C17: Transmutation I 2/4 | D17: Top @8.5–9 (target ~+25 kg), BO with fatigue stop | E17: 82–85% of Tue, 4–5 sets @7–8 | F17: 2× standard
A18: W3 | B18: May 25 – May 31 | C18: Transmutation I 3/4 | D18: Top @9 (target ~+26 kg), BO with fatigue stop | E18: 82–85% of Tue, 4–5 sets @7–8 | F18: 2× standard
A19: W4 | B19: Jun 01 – Jun 07 | C19: Transmutation I 4/4 | D19: Top @9 (target +26–27 kg) — last push before deload | E19: 82–85% of heavy, 4–5 sets @7–8 | F19: 1× (Tue primer)
A20: W5 | B20: Jun 08 – Jun 14 | C20: DELOAD + BENCHMARK | D20: Tue: 3 sets @6 deload. Sat: TEST 1 set max 5s @9–9.5 | E20: Rest | F20: skip (test wk)
A21: W6 | B21: Jun 15 – Jun 21 | C21: Transmutation II 1/4 | D21: Top @9–9.5 with NEW benchmark percentages | E21: 85–88% of heavy, 4–5 sets @8 | F21: 1× (Tue)
A22: W7 | B22: Jun 22 – Jun 28 | C22: Transmutation II 2/4 | D22: Top @9–9.5, BO with fatigue stop | E22: 85–88% of heavy, 4–5 sets @8 | F22: 1× (Tue)
A23: W8 | B23: Jun 29 – Jul 05 | C23: Transmutation II 3/4 | D23: Top @9–9.5, BO with fatigue stop | E23: 85–88% of heavy, 4–5 sets @8 | F23: 1× (Tue)
A24: W9 | B24: Jul 06 – Jul 12 | C24: Transmutation II 4/4 | D24: Top @9–9.5 push, final load before deload | E24: 85–88% of heavy, 4–5 sets @8 | F24: 1× (Tue)
A25: W10 | B25: Jul 13 – Jul 19 | C25: DELOAD + BENCHMARK | D25: Tue: 3 sets @6 deload. Sat: TEST 1 set max 5s @9–9.5 | E25: Rest | F25: skip (test wk)
A26: W11 | B26: Jul 20 – Jul 26 | C26: Peak Intensity 1/4 | D26: 3s max singles @9.5 — load from W10 3s test. 3–5 efforts, 4–5 min rest. No back-offs. | E26: 88–90% of heavy, 4–5 sets @8 | F26: 1× (Tue)
... A31: W16 | B31: Aug 24 – Aug 30 | C31: Realization — Cycle Close | D31: 2–3 singles @9 (3s or 5s). Climb hard. Apply on the wall. | E31: 2 sets at 80% bench @7 (optional) | F31: 1× (Tue)
A33: Key Concepts
A34: Tuesday top-set autoregulation | C34: Don't load based on last week's number. Load based on how 92% of last Tue's top set feels as a warmup: @7 → today has +2.5–5 kg in it; @8 → match or +2.5; @8.5+ → hold or back off.
A35: Fatigue stop (Tue back-offs) | C35: Stop back-offs when: load drop >5%, can't hit 5s, grip break before second 5, or any joint discomfort.
A36: Thursday is buffer | C36: Fixed 4–5 sets. NO opportunistic extensions. RPE creep to @8.5+ by set 3 → drop load 5%.
A37: Pre-session readiness | C37: During 70%-benchmark warmup hang, gauge RPE. Normal feels @5–6. @7+ = drop loads 5–10%. @8+ or joint pain = skip session.
A38: Week 1 is a discovery check | C38: Since this skips accumulation, Tue/Thu of W1 are the real test of how 48h between yielding sessions feels. If Thu W1 feels significantly worse than expected, that signal counts.
A39: Block progression gates | C39: Advance only if: no joint flags, benchmark stable/improving, recovery normal, fatigue stops not triggering early for 2 weeks straight.
A41: Color Legend
B42: Deload week with benchmark test
B43: Realization week — singles, low volume

Sheet Working Loads
A1: Working Loads — Single Source of Truth for Program Percentages
A2: Change the Working Max cell below and every load target in the program recalculates. Working Max = the load you can hold for 5s at @9–9.5 on a Saturday-fresh heavy day. PEAK BLOCK (W11–W14): heavy day uses 3s hangs. Establish 3s WM at W10 test and enter in a separate cell below. Thu volume stays 5s throughout.
A4: Input
A5: Working Max (kg) | B5: 25
A6: As of (date) | B6: 2026-05-22
A7: Notes | B7: Reset from +25kg given Thu @10 ceiling — recheck on rested day
A9: When to update: after any benchmark test (W5/W10/W15), or any time daily expression consistently disagrees with the current number for 2+ sessions. Increment in 0.5–2 kg steps.
A11: Key Reference Loads (% of Working Max)
A12: Reference point | B12: % of WM | C12: Load (kg) | D12: When used
A13: Warmup readiness check (70%) | B13: 0.7 | C13: =ROUND($B$5*0.7*2,0)/2 -> 17.5 | D13: 70% feeler hang during warmup
A14: Deload load (75%) | B14: 0.75 | C14: =ROUND($B$5*0.75*2,0)/2 -> 19 | D14: Tue deload set in W5/W10/W15
A15: @7 — Volume target floor | B15: 0.85 | C15: =ROUND($B$5*(40+6*7)/97*2,0)/2 -> 21 | D15: Thu volume comfortable end
A16: @8 — Volume target ceiling | B16: 0.91 | C16: =ROUND($B$5*(40+6*8)/97*2,0)/2 -> 22.5 | D16: Thu volume max RPE
A17: @8.5 — Heavy entry (Trans I) | B17: 0.94 | C17: =ROUND($B$5*(40+6*8.5)/97*2,0)/2 -> 23.5 | D17: Tue top set Trans I early
A18: @9 — Heavy push | B18: 0.97 | C18: =ROUND($B$5*(40+6*9)/97*2,0)/2 -> 24 | D18: Tue top set Trans I late / II
A19: @9.5 — Benchmark / Peak | B19: 1 | C19: =$B$5 -> 25 | D19: Test day / Peak top end
A21: Block-by-Block Target Loads
A22: Week | B22: Block | C22: Heavy RPE target | D22: Heavy top (kg) | E22: Thu % of heavy | F22: Thu volume (kg) | G22: BO % of heavy | H22: BO (kg)
A23: W1 | B23: Trans I 1/4 | C23: @8.5 | D23: =ROUND($B$5*(40+6*8.5)/97*2,0)/2 -> 23.5 | E23: 0.82 | F23: =ROUND(D23*0.82*2,0)/2 -> 19.5 | G23: 0.92 | H23: =ROUND(D23*0.92*2,0)/2 -> 21.5
A24: W2 | B24: Trans I 2/4 | C24: @8.5–9 | D24: =ROUND($B$5*(40+6*8.75)/97*2,0)/2 -> 24 | E24: 0.83 | F24: =ROUND(D24*0.83*2,0)/2 -> 20 | G24: 0.93 | H24: =ROUND(D24*0.93*2,0)/2 -> 22.5
A25: W3 | B25: Trans I 3/4 | C25: @9 | D25: =ROUND($B$5*(40+6*9)/97*2,0)/2 -> 24 | E25: 0.84 | F25: =ROUND(D25*0.84*2,0)/2 -> 20 | G25: 0.94 | H25: =ROUND(D25*0.94*2,0)/2 -> 22.5
A26: W4 | B26: Trans I 4/4 | C26: @9 | D26: =ROUND($B$5*(40+6*9)/97*2,0)/2 -> 24 | E26: 0.85 | F26: =ROUND(D26*0.85*2,0)/2 -> 20.5 | G26: 0.95 | H26: =ROUND(D26*G26*2,0)/2 -> 23
A27: W5 | B27: DELOAD + TEST | C27: Deload @6-7 / Test @9.5 | D27: =ROUND($B$5*0.75*2,0)/2 -> 19 | E27: test | F27: =$B$5 -> 25 | G27: — | H27: —
A28: W6 | B28: Trans II 1/4 | C28: @9–9.5 | D28: =ROUND($B$5*(40+6*9.25)/97*2,0)/2 -> 24.5 | E28: 0.86 | F28: =ROUND(D28*0.86*2,0)/2 -> 21 | G28: 0.82 | H28: =ROUND(D28*G28*2,0)/2 -> 20
A29: W7 | B29: Trans II 2/4 | C29: @9–9.5 | D29: =ROUND($B$5*(40+6*9.25)/97*2,0)/2 -> 24.5 | E29: 0.87 | F29: =ROUND(D29*0.87*2,0)/2 -> 21.5 | G29: 0.82 | H29: =ROUND(D29*G29*2,0)/2 -> 20
A30: W8 | B30: Trans II 3/4 | C30: @9–9.5 | D30: =ROUND($B$5*(40+6*9.25)/97*2,0)/2 -> 24.5 | E30: 0.87 | F30: =ROUND(D30*0.87*2,0)/2 -> 21.5 | G30: 0.82 | H30: =ROUND(D30*G30*2,0)/2 -> 20
A31: W9 | B31: Trans II 4/4 | C31: @9–9.5 | D31: =ROUND($B$5*(40+6*9.5)/97*2,0)/2 -> 25 | E31: 0.88 | F31: =ROUND(D31*0.88*2,0)/2 -> 22 | G31: 0.82 | H31: =ROUND(D31*G31*2,0)/2 -> 20.5
A32: W10 | B32: DELOAD + TEST | C32: Deload @6-7 / Test @9.5 | D32: =ROUND($B$5*0.75*2,0)/2 -> 19 | E32: test | F32: =$B$5 -> 25 | G32: — | H32: —
A33: W11 | B33: Peak Intensity 1/4 | C33: @9.5 | D33: =ROUND($B$5*(40+6*9.5)/97*2,0)/2 -> 25 | E33: 0.8 | F33: =ROUND(D33*0.88*2,0)/2 -> 22 | G33: 0.82 | H33: =ROUND(D33*G33*2,0)/2 -> 20.5
A34: W12 | B34: Peak Intensity 2/4 | C34: @9.5 | D34: =ROUND($B$5*(40+6*9.5)/97*2,0)/2 -> 25 | E34: 0.8 | F34: =ROUND(D34*0.89*2,0)/2 -> 22.5 | G34: 0.82 | H34: =ROUND(D34*G34*2,0)/2 -> 20.5
A35: W13 | B35: Peak Intensity 3/4 | C35: @9.5 | D35: =ROUND($B$5*(40+6*9.5)/97*2,0)/2 -> 25 | E35: 0.81 | F35: =ROUND(D35*0.89*2,0)/2 -> 22.5 | G35: 0.82 | H35: =ROUND(D35*G35*2,0)/2 -> 20.5
A36: W14 | B36: Peak Intensity 4/4 | C36: @9.5 | D36: =ROUND($B$5*(40+6*9.5)/97*2,0)/2 -> 25 | E36: 0.82 | F36: =ROUND(D36*0.9*2,0)/2 -> 22.5 | G36: 0.82 | H36: =ROUND(D36*G36*2,0)/2 -> 20.5
A37: W15 | B37: DELOAD + FINAL TEST | C37: Deload @6 / Final test @9.5 | D37: =ROUND($B$5*0.75*2,0)/2 -> 19 | E37: test | F37: =$B$5 -> 25 | G37: — | H37: —
A38: W16 | B38: Realization | C38: @9 singles | D38: =ROUND($B$5*(40+6*9)/97*2,0)/2 -> 24 | E38: 0.8 | F38: =ROUND(D38*0.8*2,0)/2 -> 19 | G38: — | H38: —
A40: How loads are derived
A41: • Working Max is anchored at @9.5 (the load you can hold 5s with nothing left). All RPE-targeted loads use the E1RM formula: Load = WM × (40 + 6×RPE) / 97
A42: • Thursday volume = % of heavy (Saturday) top set, escalating across the block. NOT a function of Working Max directly.
A43: • Back-off: 2–3 sets at genuinely @7–8 (~82% of top set, ~4–5 kg drop). Stop when RPE creeps above @8 or grip breaks before 5s.
A44: • Deload Tue load = 75% of Working Max (the program's standard). Thu of deload week = benchmark test attempt at the new Working Max.
A45: • Loads rounded to nearest 0.5 kg. Smallest practical hangboard increment.
...

Sheet Analytics
A1: Analytics — Progress Tracking for Autoregulated Training
A2: E1RM converts Load + RPE into a single comparable strength number. Trends, not single sessions, are the signal. Source data is auto-pulled from the Log; the _Data sheet holds raw aggregations.
A4: 1. E1RM Trend — Are you actually getting stronger?
A5: Two series: Tuesday heavy E1RM (pink) and Thursday volume E1RM (green). Rising line at consistent RPE = real strength gain. Flat line across 3+ sessions at same RPE = real plateau, deload soon. Volume series should track below heavy.
A26: 2. Benchmark vs Working Load Gap — How submaximal is your training?
A27: Working load (top set) as a percentage of your current best E1RM. Heavy day target = ~92–95%. Volume day target = ~80–88%. Gap consistently wider than these = under-stimulating. Consistently above = test the benchmark.
A48: 3. Recovery Trend — Early warning system
A49: Next-day feel (1 fresh → 5 sharp pain). Rolling 5-session avg (blue line) is the trend signal. Rising average across 2+ weeks = accumulated fatigue; deload regardless of strength gains. >3 average for a single session = recovery flag.
A70: 4. Weekly Summary
A71: Per-week aggregations. Watch the Avg RPE column: if it creeps up while Max E1RM stays flat, that's a deload signal.
A72: Wk | B72: Start | C72: End | D72: Block | E72: Yield | F72: OI | G72: Avg RPE | H72: Max E1RM | I72: Avg Next-Day | J72: Flag
A73: =IFERROR(_Data!A57,"") -> W1 | B73: =IFERROR(_Data!B57,"") -> 46153 | C73: =IFERROR(_Data!C57,"") -> 46159 | D73: =IFERROR(_Data!D57,"") -> Trans I 1/4 | E73: =IFERROR(_Data!E57,"") -> 2 | F73: =IFERROR(_Data!F57,"") -> 1 | G73: =IFERROR(_Data!G57,"") -> 10 | H73: =IFERROR(_Data!H57,"") -> 25 | ... J73: =IFERROR(_Data!J57,"")
A74: =IFERROR(_Data!A58,"") -> W2 | B74: =IFERROR(_Data!B58,"") -> 46160 | C74: =IFERROR(_Data!C58,"") -> 46166 | D74: =IFERROR(_Data!D58,"") -> Trans I 2/4 | E74: =IFERROR(_Data!E58,"") -> 1 | F74: =IFERROR(_Data!F58,"") -> 1 | G74: =IFERROR(_Data!G58,"") -> 10 | H74: =IFERROR(_Data!H58,"") -> 25 | ... J74: =IFERROR(_Data!J58,"")
A75: =IFERROR(_Data!A59,"") -> W3 | B75: =IFERROR(_Data!B59,"") -> 46167 | C75: =IFERROR(_Data!C59,"") -> 46173 | D75: =IFERROR(_Data!D59,"") -> Trans I 3/4 | E75: =IFERROR(_Data!E59,"") -> 2 | F75: =IFERROR(_Data!F59,"") -> 1 | G75: =IFERROR(_Data!G59,"") -> 8 | H75: =IFERROR(_Data!H59,"") -> 26.6 | ... J75: =IFERROR(_Data!J59,"") -> RECOVERY FLAG
A76: =IFERROR(_Data!A60,"") -> W4 | B76: =IFERROR(_Data!B60,"") -> 46174 | C76: =IFERROR(_Data!C60,"") -> 46180 | D76: =IFERROR(_Data!D60,"") -> Trans I 4/4 | E76: =IFERROR(_Data!E60,"") -> 0 | F76: =IFERROR(_Data!F60,"") -> 0 | G76: =IFERROR(_Data!G60,"") | H76: =IFERROR(_Data!H60,"") -> 0 | ... J76: =IFERROR(_Data!J60,"")
A77: =IFERROR(_Data!A61,"") -> W5 | B77: =IFERROR(_Data!B61,"") -> 46181 | C77: =IFERROR(_Data!C61,"") -> 46187 | D77: =IFERROR(_Data!D61,"") -> Deload + Test | E77: =IFERROR(_Data!E61,"") -> 0 | F77: =IFERROR(_Data!F61,"") -> 0 | G77: =IFERROR(_Data!G61,"") | H77: =IFERROR(_Data!H61,"") -> 0 | ... J77: =IFERROR(_Data!J61,"") -> TEST
A78: =IFERROR(_Data!A62,"") -> W6 | B78: =IFERROR(_Data!B62,"") -> 46188 | C78: =IFERROR(_Data!C62,"") -> 46194 | D78: =IFERROR(_Data!D62,"") -> Trans II 1/4 | E78: =IFERROR(_Data!E62,"") -> 0 | F78: =IFERROR(_Data!F62,"") -> 0 | G78: =IFERROR(_Data!G62,"") | H78: =IFERROR(_Data!H62,"") -> 0 | ... J78: =IFERROR(_Data!J62,"")
A79: =IFERROR(_Data!A63,"") -> W7 | B79: =IFERROR(_Data!B63,"") -> 46195 | C79: =IFERROR(_Data!C63,"") -> 46201 | D79: =IFERROR(_Data!D63,"") -> Trans II 2/4 | E79: =IFERROR(_Data!E63,"") -> 0 | F79: =IFERROR(_Data!F63,"") -> 0 | G79: =IFERROR(_Data!G63,"") | H79: =IFERROR(_Data!H63,"") -> 0 | ... J79: =IFERROR(_Data!J63,"")
A80: =IFERROR(_Data!A64,"") -> W8 | B80: =IFERROR(_Data!B64,"") -> 46202 | C80: =IFERROR(_Data!C64,"") -> 46208 | D80: =IFERROR(_Data!D64,"") -> Trans II 3/4 | E80: =IFERROR(_Data!E64,"") -> 0 | F80: =IFERROR(_Data!F64,"") -> 0 | G80: =IFERROR(_Data!G64,"") | H80: =IFERROR(_Data!H64,"") -> 0 | ... J80: =IFERROR(_Data!J64,"")
A81: =IFERROR(_Data!A65,"") -> W9 | B81: =IFERROR(_Data!B65,"") -> 46209 | C81: =IFERROR(_Data!C65,"") -> 46215 | D81: =IFERROR(_Data!D65,"") -> Trans II 4/4 | E81: =IFERROR(_Data!E65,"") -> 0 | F81: =IFERROR(_Data!F65,"") -> 0 | G81: =IFERROR(_Data!G65,"") | H81: =IFERROR(_Data!H65,"") -> 0 | ... J81: =IFERROR(_Data!J65,"")
A82: =IFERROR(_Data!A66,"") -> W10 | B82: =IFERROR(_Data!B66,"") -> 46216 | C82: =IFERROR(_Data!C66,"") -> 46222 | D82: =IFERROR(_Data!D66,"") -> Deload + Test | E82: =IFERROR(_Data!E66,"") -> 0 | F82: =IFERROR(_Data!F66,"") -> 0 | G82: =IFERROR(_Data!G66,"") | H82: =IFERROR(_Data!H66,"") -> 0 | ... J82: =IFERROR(_Data!J66,"") -> TEST
A83: =IFERROR(_Data!A67,"") -> W11 | B83: =IFERROR(_Data!B67,"") -> 46223 | C83: =IFERROR(_Data!C67,"") -> 46229 | D83: =IFERROR(_Data!D67,"") -> Peak 1/4 | E83: =IFERROR(_Data!E67,"") -> 0 | F83: =IFERROR(_Data!F67,"") -> 0 | G83: =IFERROR(_Data!G67,"") | H83: =IFERROR(_Data!H67,"") -> 0 | ... J83: =IFERROR(_Data!J67,"")
A84: =IFERROR(_Data!A68,"") -> W12 | B84: =IFERROR(_Data!B68,"") -> 46230 | C84: =IFERROR(_Data!C68,"") -> 46236 | D84: =IFERROR(_Data!D68,"") -> Peak 2/4 | E84: =IFERROR(_Data!E68,"") -> 0 | F84: =IFERROR(_Data!F68,"") -> 0 | G84: =IFERROR(_Data!G68,"") | H84: =IFERROR(_Data!H68,"") -> 0 | ... J84: =IFERROR(_Data!J68,"")
... A88: =IFERROR(_Data!A72,"") -> W16 | B88: =IFERROR(_Data!B72,"") -> 46258 | C88: =IFERROR(_Data!C72,"") -> 46264 | D88: =IFERROR(_Data!D72,"") -> Realization | E88: =IFERROR(_Data!E72,"") -> 0 | F88: =IFERROR(_Data!F72,"") -> 0 | G88: =IFERROR(_Data!G72,"") | H88: =IFERROR(_Data!H72,"") -> 0 | ... J88: =IFERROR(_Data!J72,"") -> REALIZE
A91: 5. Block Summary
A92: Per-phase aggregations. The Max E1RM column shows the actual progression milestone for each phase — that's the report card.
A93: Phase | B93: Weeks | C93: Start | D93: End | E93: Yield | F93: OI | G93: Avg RPE | H93: Max E1RM | I93: Avg Next-Day | J93: Status
A94: =IFERROR(_Data!A77,"") -> Transmutation I | B94: =IFERROR(_Data!B77,"") -> W1–W4 | C94: =IFERROR(_Data!C77,"") -> 46153 | D94: =IFERROR(_Data!D77,"") -> 46180 | E94: =IFERROR(_Data!E77,"") -> 5 | F94: =IFERROR(_Data!F77,"") -> 3 | G94: =IFERROR(_Data!G77,"") -> 9.2 | H94: =IFERROR(_Data!H77,"") -> 26.6 | ... J94: =IFERROR(_Data!J77,"") -> In progress
A95: =IFERROR(_Data!A78,"") -> Deload + Test W5 | B95: =IFERROR(_Data!B78,"") -> W5 | C95: =IFERROR(_Data!C78,"") -> 46181 | D95: =IFERROR(_Data!D78,"") -> 46187 | E95: =IFERROR(_Data!E78,"") -> 0 | F95: =IFERROR(_Data!F78,"") -> 0 | G95: =IFERROR(_Data!G78,"") | H95: =IFERROR(_Data!H78,"") -> 0 | ... J95: =IFERROR(_Data!J78,"") -> Upcoming
A96: =IFERROR(_Data!A79,"") -> Transmutation II | B96: =IFERROR(_Data!B79,"") -> W6–W9 | C96: =IFERROR(_Data!C79,"") -> 46188 | D96: =IFERROR(_Data!D79,"") -> 46215 | E96: =IFERROR(_Data!E79,"") -> 0 | F96: =IFERROR(_Data!F79,"") -> 0 | G96: =IFERROR(_Data!G79,"") | H96: =IFERROR(_Data!H79,"") -> 0 | ... J96: =IFERROR(_Data!J79,"") -> Upcoming
A97: =IFERROR(_Data!A80,"") -> Deload + Test W10 | B97: =IFERROR(_Data!B80,"") -> W10 | C97: =IFERROR(_Data!C80,"") -> 46216 | D97: =IFERROR(_Data!D80,"") -> 46222 | E97: =IFERROR(_Data!E80,"") -> 0 | F97: =IFERROR(_Data!F80,"") -> 0 | G97: =IFERROR(_Data!G80,"") | H97: =IFERROR(_Data!H80,"") -> 0 | ... J97: =IFERROR(_Data!J80,"") -> Upcoming
A98: =IFERROR(_Data!A81,"") -> Peak Intensity | B98: =IFERROR(_Data!B81,"") -> W11–W14 | C98: =IFERROR(_Data!C81,"") -> 46223 | D98: =IFERROR(_Data!D81,"") -> 46250 | E98: =IFERROR(_Data!E81,"") -> 0 | F98: =IFERROR(_Data!F81,"") -> 0 | G98: =IFERROR(_Data!G81,"") | H98: =IFERROR(_Data!H81,"") -> 0 | ... J98: =IFERROR(_Data!J81,"") -> Upcoming
A99: =IFERROR(_Data!A82,"") -> Deload + Final Test | B99: =IFERROR(_Data!B82,"") -> W15 | C99: =IFERROR(_Data!C82,"") -> 46251 | D99: =IFERROR(_Data!D82,"") -> 46257 | E99: =IFERROR(_Data!E82,"") -> 0 | F99: =IFERROR(_Data!F82,"") -> 0 | G99: =IFERROR(_Data!G82,"") | H99: =IFERROR(_Data!H82,"") -> 0 | ... J99: =IFERROR(_Data!J82,"") -> Upcoming
A100: =IFERROR(_Data!A83,"") -> Realization | B100: =IFERROR(_Data!B83,"") -> W16 | C100: =IFERROR(_Data!C83,"") -> 46258 | D100: =IFERROR(_Data!D83,"") -> 46264 | E100: =IFERROR(_Data!E83,"") -> 0 | F100: =IFERROR(_Data!F83,"") -> 0 | G100: =IFERROR(_Data!G83,"") | H100: =IFERROR(_Data!H83,"") -> 0 | ... J100: =IFERROR(_Data!J83,"") -> Upcoming
A103: Reading the Analytics
A104: Green flag (program working) | D104: E1RM trending up week-over-week. Avg RPE stable in target zone (Tue ~8.5–9, Thu ~7–8). Avg Next-Day Feel ≤2.5. Working % around 92–95% on heavy days. → Hold course, progress as planned.
A105: Yellow flag (caution) | D105: E1RM flat for 2+ weeks at same RPE. OR Avg RPE creeping up while load is held. OR Avg Next-Day Feel drifting above 2.5. → Drop Thursday volume one set, ensure deload not skipped, evaluate sleep.
A106: Red flag (back off) | D106: E1RM declining 2+ weeks. OR weekly Avg Next-Day Feel >3 (recovery flag in summary). OR any joint inflammation signal in notes. → Stop loaded finger work or drop to deload loads. Apply exit criteria from Reference.
A107: Benchmark gap interpretation | D107: Heavy day working % consistently below ~90% with target RPE → benchmark is stale, you're submaximally training. Run a benchmark test ahead of schedule. Working % consistently above ~95% → load is creeping ahead of true strength; back off and let recovery catch up.
A108: Block decision (use at end of each block) | D108: Block Summary row gives the snapshot. If Max E1RM at end > Max E1RM at start AND status=Complete AND no red flags during → advance to next block. Else → repeat block or insert extra deload.

Sheet Log
A1: Session Log
A2: LOG GUIDE — only fill what applies: HEAVY 5s (Trans) → Type=Yielding Role=Heavy HEAVY 3s (Peak) → Type=Yielding Role=Heavy-3s Load=top-set kg RPE=top-set RPE Sets=back-offs completed VOLUME (Thu) → Type=Yielding Role=Volume Load=working kg RPE=working RPE Sets=sets done (e.g. 4) OI (Tue) → Type=OI Role=OI Load & RPE = leave blank Sets=OI sets done CLIMB → Type=Climbing Role=Climb Load / RPE / Sets = leave blank TEST (Sat) → Type=Yielding Role=Test Load=max tested kg RPE=9–9.5 DELOAD (Tue) → Type=Yielding Role=Deload Load=deload kg RPE Sets=sets done Always fill: Date, Taxing (1–5), Next-Day Feel (1–5). Felt (1–10) and Notes optional but useful. E1RM auto-calculates for all Yielding sessions (Heavy, Volume, Test, Deload).
A4: Date | B4: Type (Yielding / OI / Climbing) | C4: Venue | D4: Role (Heavy / Volume / OI / Climb / Test / Deload) | E4: Load (kg) | F4: Top Set RPE | G4: Sets | H4: Session Taxing (1-5) | I4: Felt (1-10) | J4: Next-Day Feel (1-5) | K4: Block | L4: Notes | M4: E1RM (kg) [5s-equiv; Heavy-3s ÷1.1]
A5: 46126 | B5: Yielding | C5: Board | E5: 20 | H5: 3 | I5: 5 | J5: 3 | K5: Accumulation | L5: Felt easy at +25kg, 1-2s left in tank | M5: =IF(OR(B5<>"Yielding",E5="",F5="",F5<6),"",IF(D5="Heavy-3s",ROUND(E5*100/(40+6*F5)/1.1,1),ROUND(E5*100/(40+6*F5),1)))
A6: 46133 | B6: Climbing | C6: Outdoor | E6: 0 | H6: 2 | I6: 5 | J6: 2 | K6: Accumulation | L6: Outdoor easy | M6: =IF(OR(B6<>"Yielding",E6="",F6="",F6<6),"",IF(D6="Heavy-3s",ROUND(E6*100/(40+6*F6)/1.1,1),ROUND(E6*100/(40+6*F6),1)))
A7: 46134 | B7: Yielding | C7: Board | E7: 25 | H7: 2 | I7: 5 | J7: 3 | K7: Accumulation | L7: Felt weaker, bit hurt finger | M7: =IF(OR(B7<>"Yielding",E7="",F7="",F7<6),"",IF(D7="Heavy-3s",ROUND(E7*100/(40+6*F7)/1.1,1),ROUND(E7*100/(40+6*F7),1)))
A8: 46136 | B8: OI | C8: Gym | E8: 0 | H8: 2 | I8: 5 | J8: 2 | K8: Accumulation | L8: Project attempts, cold | M8: =IF(OR(B8<>"Yielding",E8="",F8="",F8<6),"",IF(D8="Heavy-3s",ROUND(E8*100/(40+6*F8)/1.1,1),ROUND(E8*100/(40+6*F8),1)))
A9: 46140 | B9: OI | C9: Gym | E9: 0 | H9: 1 | I9: 5 | J9: 2 | K9: Accumulation | L9: Tired after work | M9: =IF(OR(B9<>"Yielding",E9="",F9="",F9<6),"",IF(D9="Heavy-3s",ROUND(E9*100/(40+6*F9)/1.1,1),ROUND(E9*100/(40+6*F9),1)))
A10: 46142 | B10: OI | C10: Gym | E10: 0 | H10: 3 | I10: 5 | J10: 3 | K10: Accumulation | L10: Struggle to express power | M10: =IF(OR(B10<>"Yielding",E10="",F10="",F10<6),"",IF(D10="Heavy-3s",ROUND(E10*100/(40+6*F10)/1.1,1),ROUND(E10*100/(40+6*F10),1)))
A11: 46143 | B11: Yielding | C11: Board | E11: 15 | H11: 4 | I11: 5 | J11: 2 | K11: Accumulation | L11: Good session, good execution, sent project | M11: =IF(OR(B11<>"Yielding",E11="",F11="",F11<6),"",IF(D11="Heavy-3s",ROUND(E11*100/(40+6*F11)/1.1,1),ROUND(E11*100/(40+6*F11),1)))
A12: 46146 | B12: Yielding | C12: Board | E12: 20 | H12: 3 | I12: 8 | J12: 2 | K12: Accumulation | L12: Low energy but felt strong | M12: =IF(OR(B12<>"Yielding",E12="",F12="",F12<6),"",IF(D12="Heavy-3s",ROUND(E12*100/(40+6*F12)/1.1,1),ROUND(E12*100/(40+6*F12),1)))
A13: 46149 | B13: OI | C13: Gym | E13: 0 | H13: 4 | I13: 8 | J13: 2 | K13: Accumulation | L13: Felt good, sent alot, but felt dead fast. Low food | M13: =IF(OR(B13<>"Yielding",E13="",F13="",F13<6),"",IF(D13="Heavy-3s",ROUND(E13*100/(40+6*F13)/1.1,1),ROUND(E13*100/(40+6*F13),1)))
A14: 46151 | B14: Climbing | C14: Outdoor | H14: 2 | I14: 7 | J14: 3 | K14: Accumulation | L14: Fun session, might go hangboard tomorrow | M14: =IF(OR(B14<>"Yielding",E14="",F14="",F14<6),"",IF(D14="Heavy-3s",ROUND(E14*100/(40+6*F14)/1.1,1),ROUND(E14*100/(40+6*F14),1)))
A15: 46152 | B15: OI | C15: Other | D15: OI | E15: 0 | H15: 3 | I15: 6 | J15: 3 | K15: Accumulation | L15: Did some hb, felt abit tired | M15: =IF(OR(B15<>"Yielding",E15="",F15="",F15<6),"",IF(D15="Heavy-3s",ROUND(E15*100/(40+6*F15)/1.1,1),ROUND(E15*100/(40+6*F15),1)))
A16: 46154 | B16: Yielding | C16: Board | D16: Heavy | E16: 25 | F16: 10 | G16: 3 | H16: 3 | I16: 6 | J16: 2 | K16: Trans I 1/4 | L16: Felt ok on hb, but tired spray sesh | M16: =IF(OR(B16<>"Yielding",E16="",F16="",F16<6),"",IF(D16="Heavy-3s",ROUND(E16*100/(40+6*F16)/1.1,1),ROUND(E16*100/(40+6*F16),1))) -> 25
A17: 46156 | B17: Yielding | C17: Gym | D17: Volume | E17: 20 | F17: 10 | G17: 3 | H17: 3 | I17: 3 | J17: 4 | K17: Trans I 1/4 | L17: Felt weak, tired, hb weak | M17: =IF(OR(B17<>"Yielding",E17="",F17="",F17<6),"",IF(D17="Heavy-3s",ROUND(E17*100/(40+6*F17)/1.1,1),ROUND(E17*100/(40+6*F17),1))) -> 20
A18: 46158 | B18: OI | C18: Gym | D18: OI | E18: 0 | G18: 0 | H18: 1 | I18: 2 | J18: 3 | K18: Trans I 1/4 | L18: Week sesh, hangout tired sore | M18: =IF(OR(B18<>"Yielding",E18="",F18="",F18<6),"",IF(D18="Heavy-3s",ROUND(E18*100/(40+6*F18)/1.1,1),ROUND(E18*100/(40+6*F18),1)))
A19: 46161 | B19: Yielding | C19: Other | D19: Heavy | E19: 25 | F19: 10 | G19: 3 | H19: 1 | I19: 4 | J19: 3 | K19: Trans I 1/4 | L19: Only hb, felt disconnected | M19: =IF(OR(B19<>"Yielding",E19="",F19="",F19<6),"",IF(D19="Heavy-3s",ROUND(E19*100/(40+6*F19)/1.1,1),ROUND(E19*100/(40+6*F19),1))) -> 25
A20: 46166 | B20: OI | C20: Gym | D20: OI | E20: 0 | H20: 4 | I20: 6 | J20: 3 | K20: Trans I 1/4 | L20: Felt ok after a long rest | M20: =IF(OR(B20<>"Yielding",E20="",F20="",F20<6),"",IF(D20="Heavy-3s",ROUND(E20*100/(40+6*F20)/1.1,1),ROUND(E20*100/(40+6*F20),1)))
A21: 46168 | B21: Yielding | C21: Board | D21: Heavy | E21: 25 | F21: 9 | G21: 3 | H21: 3 | I21: 8 | J21: 4 | K21: Trans I 1/4 | L21: Felt strong on hb, 25 felt controlled, spray was easy | M21: =IF(OR(B21<>"Yielding",E21="",F21="",F21<6),"",IF(D21="Heavy-3s",ROUND(E21*100/(40+6*F21)/1.1,1),ROUND(E21*100/(40+6*F21),1))) -> 26.6
A22: 46170 | B22: OI | C22: Gym | D22: OI | H22: 4 | I22: 5 | J22: 3 | K22: Trans I 1/4 | L22: Tired after work | M22: =IF(OR(B22<>"Yielding",E22="",F22="",F22<6),"",IF(D22="Heavy-3s",ROUND(E22*100/(40+6*F22)/1.1,1),ROUND(E22*100/(40+6*F22),1)))
A23: 46173 | B23: Yielding | C23: Other | D23: Volume | E23: 20 | F23: 7 | G23: 5 | H23: 2 | I23: 7 | J23: 3 | K23: Trans I 1/4 | L23: Good sesh ggs! | M23: =IF(OR(B23<>"Yielding",E23="",F23="",F23<6),"",IF(D23="Heavy-3s",ROUND(E23*100/(40+6*F23)/1.1,1),ROUND(E23*100/(40+6*F23),1))) -> 24.4
M24: =IF(OR(B24<>"Yielding",E24="",F24="",F24<6),"",IF(D24="Heavy-3s",ROUND(E24*100/(40+6*F24)/1.1,1),ROUND(E24*100/(40+6*F24),1)))
M25: =IF(OR(B25<>"Yielding",E25="",F25="",F25<6),"",IF(D25="Heavy-3s",ROUND(E25*100/(40+6*F25)/1.1,1),ROUND(E25*100/(40+6*F25),1)))
M26: =IF(OR(B26<>"Yielding",E26="",F26="",F26<6),"",IF(D26="Heavy-3s",ROUND(E26*100/(40+6*F26)/1.1,1),ROUND(E26*100/(40+6*F26),1)))
M27: =IF(OR(B27<>"Yielding",E27="",F27="",F27<6),"",IF(D27="Heavy-3s",ROUND(E27*100/(40+6*F27)/1.1,1),ROUND(E27*100/(40+6*F27),1)))
M28: =IF(OR(B28<>"Yielding",E28="",F28="",F28<6),"",IF(D28="Heavy-3s",ROUND(E28*100/(40+6*F28)/1.1,1),ROUND(E28*100/(40+6*F28),1)))
M29: =IF(OR(B29<>"Yielding",E29="",F29="",F29<6),"",IF(D29="Heavy-3s",ROUND(E29*100/(40+6*F29)/1.1,1),ROUND(E29*100/(40+6*F29),1)))
M30: =IF(OR(B30<>"Yielding",E30="",F30="",F30<6),"",IF(D30="Heavy-3s",ROUND(E30*100/(40+6*F30)/1.1,1),ROUND(E30*100/(40+6*F30),1)))
M31: =IF(OR(B31<>"Yielding",E31="",F31="",F31<6),"",IF(D31="Heavy-3s",ROUND(E31*100/(40+6*F31)/1.1,1),ROUND(E31*100/(40+6*F31),1)))
M32: =IF(OR(B32<>"Yielding",E32="",F32="",F32<6),"",IF(D32="Heavy-3s",ROUND(E32*100/(40+6*F32)/1.1,1),ROUND(E32*100/(40+6*F32),1)))
M33: =IF(OR(B33<>"Yielding",E33="",F33="",F33<6),"",IF(D33="Heavy-3s",ROUND(E33*100/(40+6*F33)/1.1,1),ROUND(E33*100/(40+6*F33),1)))
M34: =IF(OR(B34<>"Yielding",E34="",F34="",F34<6),"",IF(D34="Heavy-3s",ROUND(E34*100/(40+6*F34)/1.1,1),ROUND(E34*100/(40+6*F34),1)))
M35: =IF(OR(B35<>"Yielding",E35="",F35="",F35<6),"",IF(D35="Heavy-3s",ROUND(E35*100/(40+6*F35)/1.1,1),ROUND(E35*100/(40+6*F35),1)))
... M300: =IF(OR(B300<>"Yielding",E300="",F300="",F300<6),"",IF(D300="Heavy-3s",ROUND(E300*100/(40+6*F300)/1.1,1),ROUND(E300*100/(40+6*F300),1)))
M301: =IF(OR(B301<>"Yielding",E301="",F301="",F301<6),"",ROUND(E301*100/(40+6*F301),1))
M302: =IF(OR(B302<>"Yielding",E302="",F302="",F302<6),"",ROUND(E302*100/(40+6*F302),1))
M303: =IF(OR(B303<>"Yielding",E303="",F303="",F303<6),"",ROUND(E303*100/(40+6*F303),1))
M304: =IF(OR(B304<>"Yielding",E304="",F304="",F304<6),"",ROUND(E304*100/(40+6*F304),1))
M305: =IF(OR(B305<>"Yielding",E305="",F305="",F305<6),"",ROUND(E305*100/(40+6*F305),1))
...

Sheet Weekly Plan
A1: Weekly Plan — 16-Week Program, Transmutation Entry
A2: From W4 on: Tue = OI primer + limit board, Thu = volume yielding, Sat = heavy yielding, Sun = rest (3 finger sessions/wk). W1–W3 ran the old Tue-heavy / Sat–Sun-OI layout and are left as completed. Fill the Done?/Actual column after each session. Update Reference if benchmark changes after a test.
A4: W1 | B4: May 11 – May 17, 2026 | C4: Transmutation I (W1 of 4) — Discovery week
A5: Focus: | B5: First week of 2x yielding. Tue at @8.5 target. Pay attention to how Thursday feels relative to Tuesday — that 48h gap is the unknown variable.
A6: Day | B6: Session | C6: Target / Loads / Sets | D6: RPE Target | E6: Done? / Actual
A7: Mon | B7: Rest | C7: No fingers. Easy mobility / sleep priority. | D7: —
A8: Tue | B8: YIELDING — Heavy | C8: Warmup → Top set @8.5 (target ~+24 kg, 7s) | 3 back-offs at 92–95% with fatigue stop | D8: @8.5 / @8 | E8: Done
A9: Wed | B9: Rest or easy climbing | C9: Jugs / volume only, no max fingers. | D9: —
A10: Thu | B10: YIELDING — Volume | C10: 82–85% of Tue top set, 4 sets, 7s (FIXED — no extensions in W1) | If RPE creeps to @8.5+ by set 3, drop load 5% and finish remaining sets. End early only if joint discomfort. | D10: @7–8 | E10: Done
A11: Fri | B11: Rest or easy climbing | C11: — | D11: —
A12: Sat | B12: OI — Beastmaker 22mm | C12: 4–5 sets max squeeze, 5–7s, 3–5 min rest | D12: Max neural | E12: Done
A13: Sun | B13: OI — Beastmaker 22mm | C13: 4–5 sets max squeeze, 5–7s, 3–5 min rest | D13: Max neural
A15: W2 | B15: May 18 – May 24, 2026 | C15: Transmutation I (W2 of 4)
A16: Focus: | B16: If W1 felt manageable, increment Tue top set toward @9. Thursday can extend to 5 sets if W1 Thursday was clean.
A17: Day | B17: Session | C17: Target / Loads / Sets | D17: RPE Target | E17: Done? / Actual
A18: Mon | B18: Rest | C18: — | D18: —
A19: Tue | B19: YIELDING — Heavy | C19: Top set @8.5–9 (target ~+25 kg) | 3–5 back-offs at 92–95%, fatigue stop on | D19: @8.5–9 / @8 | E19: Done
A20: Wed | B20: Rest or easy climbing | C20: — | D20: —
A21: Thu | B21: YIELDING — Volume | C21: 82–85% of Tue top set, 4–5 sets, 7s (FIXED) | If RPE creeps to @8.5+ by set 3, drop load 5% and finish remaining sets. End early only if joint discomfort. | D21: @7–8 | E21: Skipped
A22: Fri | B22: Rest or easy climbing | C22: — | D22: —
A23: Sat | B23: OI — Beastmaker 22mm | C23: 4–5 sets | D23: Max neural | E23: Done
A24: Sun | B24: OI — Beastmaker 22mm | C24: 4–5 sets | D24: Max neural
A26: W3 | B26: May 25 – May 31, 2026 | C26: Transmutation I (W3 of 4)
A27: Focus: | B27: Holding @9 ceiling. Small increment if last Tue top set felt @8 rather than @9.
A28: Day | B28: Session | C28: Target / Loads / Sets | D28: RPE Target | E28: Done? / Actual
A29: Mon | B29: Rest | C29: — | D29: —
A30: Tue | B30: YIELDING — Heavy | C30: Top set @9 (target ~+26 kg) | 3–5 back-offs, fatigue stop | D30: @9 / @8 | E30: Done
A31: Wed | B31: Rest or easy climbing | C31: — | D31: —
A32: Thu | B32: YIELDING — Volume | C32: 82–85% of Tue top set, 4–5 sets (FIXED) | If RPE creeps to @8.5+ by set 3, drop load 5% and finish remaining sets. End early only if joint discomfort. | D32: @7–8 | E32: Done
A33: Fri | B33: Rest or easy climbing | C33: — | D33: —
A34: Sat | B34: OI — Beastmaker 22mm | C34: 4–5 sets | D34: Max neural | E34: Done
A35: Sun | B35: OI — Beastmaker 22mm | C35: 4–5 sets | D35: Max neural
A37: W4 | B37: Jun 01 – Jun 07, 2026 | C37: Transmutation I (W4 of 4) — Last push
A38: Focus: | B38: Final push before deload. Set the top of T1 — should be +26–27 kg @9 if progression has been clean.
A39: Day | B39: Session | C39: Target / Loads / Sets | D39: RPE Target | E39: Done? / Actual
A40: Mon | B40: Rest | C40: — | D40: —
A41: Tue | B41: OI primer + LIMIT BOARD | C41: OI primer: 3–4 sets max squeeze, 5s, full rest (potentiate) → then limit boulder session | D41: Max neural / board
A42: Wed | B42: Rest or easy climbing | C42: — | D42: —
A43: Thu | B43: YIELDING — Volume | C43: 4–5 sets @ ~20.5 kg (85% of heavy top set) — FIXED, no extensions | If RPE creeps to @8.5+ by set 3, drop load 5% and finish remaining sets. End early only if joint discomfort. | D43: @7–8
A44: Fri | B44: Rest or easy climbing | C44: — | D44: —
...

Sheet Progression
A1: Progression
A2: Auto-summarized from the Log tab. Add sessions to Log and these stats update.
A4: Current Stats | D4: Recent Yielding Sessions
A5: Current yielding benchmark (max top set load) | B5: =IFERROR(SUMPRODUCT(MAX((Log!B5:B404="Yielding")*N(Log!E5:E404))),"") -> 25 | D5: Date | E5: Top Set (kg) | F5: RPE | G5: Day Role
A6: Last yielding top set load (kg) | B6: =IFERROR(LOOKUP(2,1/((Log!B5:B404="Yielding")*(Log!E5:E404<>"")),Log!E5:E404),"") -> 20 | D6: {=IFERROR(IF(SUMPRODUCT(LARGE((Log!B5:B404="Yielding")*ROW(Log!B5:B404),1))=0,"",INDEX(Log!A:A,SUMPRODUCT(LARGE((Log!B5:B404="Yielding")*ROW(Log!B5:B404),1)))),"")} -> 46173 | E6: {=IFERROR(IF(SUMPRODUCT(LARGE((Log!B5:B404="Yielding")*ROW(Log!B5:B404),1))=0,"",INDEX(Log!E:E,SUMPRODUCT(LARGE((Log!B5:B404="Yielding")*ROW(Log!B5:B404),1)))),"")} -> 20 | F6: {=IFERROR(IF(SUMPRODUCT(LARGE((Log!B5:B404="Yielding")*ROW(Log!B5:B404),1))=0,"",INDEX(Log!F:F,SUMPRODUCT(LARGE((Log!B5:B404="Yielding")*ROW(Log!B5:B404),1)))),"")} -> 7 | G6: {=IFERROR(IF(SUMPRODUCT(LARGE((Log!B5:B404="Yielding")*ROW(Log!B5:B404),1))=0,"",INDEX(Log!D:D,SUMPRODUCT(LARGE((Log!B5:B404="Yielding")*ROW(Log!B5:B404),1)))),"")} -> Volume
A7: Last yielding date | B7: =IFERROR(LOOKUP(2,1/((Log!B5:B404="Yielding")*(Log!E5:E404<>"")),Log!A5:A404),"") -> 46173 | D7: {=IFERROR(IF(SUMPRODUCT(LARGE((Log!B5:B404="Yielding")*ROW(Log!B5:B404),2))=0,"",INDEX(Log!A:A,SUMPRODUCT(LARGE((Log!B5:B404="Yielding")*ROW(Log!B5:B404),2)))),"")} -> 46168 | E7: {=IFERROR(IF(SUMPRODUCT(LARGE((Log!B5:B404="Yielding")*ROW(Log!B5:B404),2))=0,"",INDEX(Log!E:E,SUMPRODUCT(LARGE((Log!B5:B404="Yielding")*ROW(Log!B5:B404),2)))),"")} -> 25 | F7: {=IFERROR(IF(SUMPRODUCT(LARGE((Log!B5:B404="Yielding")*ROW(Log!B5:B404),2))=0,"",INDEX(Log!F:F,SUMPRODUCT(LARGE((Log!B5:B404="Yielding")*ROW(Log!B5:B404),2)))),"")} -> 9 | G7: {=IFERROR(IF(SUMPRODUCT(LARGE((Log!B5:B404="Yielding")*ROW(Log!B5:B404),2))=0,"",INDEX(Log!D:D,SUMPRODUCT(LARGE((Log!B5:B404="Yielding")*ROW(Log!B5:B404),2)))),"")} -> Heavy
A8: Last yielding RPE | B8: =IFERROR(LOOKUP(2,1/((Log!B5:B404="Yielding")*(Log!F5:F404<>"")),Log!F5:F404),"") -> 7 | D8: {=IFERROR(IF(SUMPRODUCT(LARGE((Log!B5:B404="Yielding")*ROW(Log!B5:B404),3))=0,"",INDEX(Log!A:A,SUMPRODUCT(LARGE((Log!B5:B404="Yielding")*ROW(Log!B5:B404),3)))),"")} -> 46161 | E8: {=IFERROR(IF(SUMPRODUCT(LARGE((Log!B5:B404="Yielding")*ROW(Log!B5:B404),3))=0,"",INDEX(Log!E:E,SUMPRODUCT(LARGE((Log!B5:B404="Yielding")*ROW(Log!B5:B404),3)))),"")} -> 25 | F8: {=IFERROR(IF(SUMPRODUCT(LARGE((Log!B5:B404="Yielding")*ROW(Log!B5:B404),3))=0,"",INDEX(Log!F:F,SUMPRODUCT(LARGE((Log!B5:B404="Yielding")*ROW(Log!B5:B404),3)))),"")} -> 10 | G8: {=IFERROR(IF(SUMPRODUCT(LARGE((Log!B5:B404="Yielding")*ROW(Log!B5:B404),3))=0,"",INDEX(Log!D:D,SUMPRODUCT(LARGE((Log!B5:B404="Yielding")*ROW(Log!B5:B404),3)))),"")} -> Heavy
A9: Total yielding sessions | B9: =COUNTIF(Log!B5:B404,"Yielding") -> 9 | D9: {=IFERROR(IF(SUMPRODUCT(LARGE((Log!B5:B404="Yielding")*ROW(Log!B5:B404),4))=0,"",INDEX(Log!A:A,SUMPRODUCT(LARGE((Log!B5:B404="Yielding")*ROW(Log!B5:B404),4)))),"")} -> 46156 | E9: {=IFERROR(IF(SUMPRODUCT(LARGE((Log!B5:B404="Yielding")*ROW(Log!B5:B404),4))=0,"",INDEX(Log!E:E,SUMPRODUCT(LARGE((Log!B5:B404="Yielding")*ROW(Log!B5:B404),4)))),"")} -> 20 | F9: {=IFERROR(IF(SUMPRODUCT(LARGE((Log!B5:B404="Yielding")*ROW(Log!B5:B404),4))=0,"",INDEX(Log!F:F,SUMPRODUCT(LARGE((Log!B5:B404="Yielding")*ROW(Log!B5:B404),4)))),"")} -> 10 | G9: {=IFERROR(IF(SUMPRODUCT(LARGE((Log!B5:B404="Yielding")*ROW(Log!B5:B404),4))=0,"",INDEX(Log!D:D,SUMPRODUCT(LARGE((Log!B5:B404="Yielding")*ROW(Log!B5:B404),4)))),"")} -> Volume
A10: Total OI sessions | B10: =COUNTIF(Log!B5:B404,"OI") -> 8 | D10: {=IFERROR(IF(SUMPRODUCT(LARGE((Log!B5:B404="Yielding")*ROW(Log!B5:B404),5))=0,"",INDEX(Log!A:A,SUMPRODUCT(LARGE((Log!B5:B404="Yielding")*ROW(Log!B5:B404),5)))),"")} -> 46154 | E10: {=IFERROR(IF(SUMPRODUCT(LARGE((Log!B5:B404="Yielding")*ROW(Log!B5:B404),5))=0,"",INDEX(Log!E:E,SUMPRODUCT(LARGE((Log!B5:B404="Yielding")*ROW(Log!B5:B404),5)))),"")} -> 25 | F10: {=IFERROR(IF(SUMPRODUCT(LARGE((Log!B5:B404="Yielding")*ROW(Log!B5:B404),5))=0,"",INDEX(Log!F:F,SUMPRODUCT(LARGE((Log!B5:B404="Yielding")*ROW(Log!B5:B404),5)))),"")} -> 10 | G10: {=IFERROR(IF(SUMPRODUCT(LARGE((Log!B5:B404="Yielding")*ROW(Log!B5:B404),5))=0,"",INDEX(Log!D:D,SUMPRODUCT(LARGE((Log!B5:B404="Yielding")*ROW(Log!B5:B404),5)))),"")} -> Heavy
A11: Total climbing sessions | B11: =COUNTIF(Log!B5:B404,"Climbing") -> 2 | D11: {=IFERROR(IF(SUMPRODUCT(LARGE((Log!B5:B404="Yielding")*ROW(Log!B5:B404),6))=0,"",INDEX(Log!A:A,SUMPRODUCT(LARGE((Log!B5:B404="Yielding")*ROW(Log!B5:B404),6)))),"")} -> 46146 | E11: {=IFERROR(IF(SUMPRODUCT(LARGE((Log!B5:B404="Yielding")*ROW(Log!B5:B404),6))=0,"",INDEX(Log!E:E,SUMPRODUCT(LARGE((Log!B5:B404="Yielding")*ROW(Log!B5:B404),6)))),"")} -> 20 | F11: =IFERROR(IF(SUMPRODUCT(LARGE((Log!B5:B404="Yielding")*ROW(Log!B5:B404),6))=0,"",INDEX(Log!F:F,SUMPRODUCT(LARGE((Log!B5:B404="Yielding")*ROW(Log!B5:B404),6)))),"") -> 0 | G11: =IFERROR(IF(SUMPRODUCT(LARGE((Log!B5:B404="Yielding")*ROW(Log!B5:B404),6))=0,"",INDEX(Log!D:D,SUMPRODUCT(LARGE((Log!B5:B404="Yielding")*ROW(Log!B5:B404),6)))),"") -> 0
A12: Avg next-day feel (last 10 sessions) | B12: =IFERROR(AVERAGE(OFFSET(Log!J5,MAX(0,COUNTA(Log!A5:A404)-10),0,MIN(10,COUNTA(Log!A5:A404)),1)),"") -> 3.1 | D12: {=IFERROR(IF(SUMPRODUCT(LARGE((Log!B5:B404="Yielding")*ROW(Log!B5:B404),7))=0,"",INDEX(Log!A:A,SUMPRODUCT(LARGE((Log!B5:B404="Yielding")*ROW(Log!B5:B404),7)))),"")} -> 46143 | E12: {=IFERROR(IF(SUMPRODUCT(LARGE((Log!B5:B404="Yielding")*ROW(Log!B5:B404),7))=0,"",INDEX(Log!E:E,SUMPRODUCT(LARGE((Log!B5:B404="Yielding")*ROW(Log!B5:B404),7)))),"")} -> 15 | F12: =IFERROR(IF(SUMPRODUCT(LARGE((Log!B5:B404="Yielding")*ROW(Log!B5:B404),7))=0,"",INDEX(Log!F:F,SUMPRODUCT(LARGE((Log!B5:B404="Yielding")*ROW(Log!B5:B404),7)))),"") -> 0 | G12: =IFERROR(IF(SUMPRODUCT(LARGE((Log!B5:B404="Yielding")*ROW(Log!B5:B404),7))=0,"",INDEX(Log!D:D,SUMPRODUCT(LARGE((Log!B5:B404="Yielding")*ROW(Log!B5:B404),7)))),"") -> 0
A13: Avg top set RPE (last 5 yielding) | B13: =IFERROR(AVERAGEIF(OFFSET(Log!F5,MAX(0,COUNTIF(Log!B5:B404,"Yielding")-5),0,MIN(5,COUNTIF(Log!B5:B404,"Yielding")),1),"<>"),"") | D13: {=IFERROR(IF(SUMPRODUCT(LARGE((Log!B5:B404="Yielding")*ROW(Log!B5:B404),8))=0,"",INDEX(Log!A:A,SUMPRODUCT(LARGE((Log!B5:B404="Yielding")*ROW(Log!B5:B404),8)))),"")} -> 46134 | E13: {=IFERROR(IF(SUMPRODUCT(LARGE((Log!B5:B404="Yielding")*ROW(Log!B5:B404),8))=0,"",INDEX(Log!E:E,SUMPRODUCT(LARGE((Log!B5:B404="Yielding")*ROW(Log!B5:B404),8)))),"")} -> 25 | F13: =IFERROR(IF(SUMPRODUCT(LARGE((Log!B5:B404="Yielding")*ROW(Log!B5:B404),8))=0,"",INDEX(Log!F:F,SUMPRODUCT(LARGE((Log!B5:B404="Yielding")*ROW(Log!B5:B404),8)))),"") -> 0 | G13: =IFERROR(IF(SUMPRODUCT(LARGE((Log!B5:B404="Yielding")*ROW(Log!B5:B404),8))=0,"",INDEX(Log!D:D,SUMPRODUCT(LARGE((Log!B5:B404="Yielding")*ROW(Log!B5:B404),8)))),"") -> 0
A14: Yellow-flag sessions (Strength Felt ≤ 5) | B14: =COUNTIFS(Log!I5:I404,"<=5",Log!B5:B404,"<>Climbing") -> 10 | D14: {=IFERROR(IF(SUMPRODUCT(LARGE((Log!B5:B404="Yielding")*ROW(Log!B5:B404),9))=0,"",INDEX(Log!A:A,SUMPRODUCT(LARGE((Log!B5:B404="Yielding")*ROW(Log!B5:B404),9)))),"")} -> 46126 | E14: {=IFERROR(IF(SUMPRODUCT(LARGE((Log!B5:B404="Yielding")*ROW(Log!B5:B404),9))=0,"",INDEX(Log!E:E,SUMPRODUCT(LARGE((Log!B5:B404="Yielding")*ROW(Log!B5:B404),9)))),"")} -> 20 | F14: =IFERROR(IF(SUMPRODUCT(LARGE((Log!B5:B404="Yielding")*ROW(Log!B5:B404),9))=0,"",INDEX(Log!F:F,SUMPRODUCT(LARGE((Log!B5:B404="Yielding")*ROW(Log!B5:B404),9)))),"") -> 0 | G14: =IFERROR(IF(SUMPRODUCT(LARGE((Log!B5:B404="Yielding")*ROW(Log!B5:B404),9))=0,"",INDEX(Log!D:D,SUMPRODUCT(LARGE((Log!B5:B404="Yielding")*ROW(Log!B5:B404),9)))),"") -> 0
D15: {=IFERROR(IF(SUMPRODUCT(LARGE((Log!B5:B404="Yielding")*ROW(Log!B5:B404),10))=0,"",INDEX(Log!A:A,SUMPRODUCT(LARGE((Log!B5:B404="Yielding")*ROW(Log!B5:B404),10)))),"")} | E15: {=IFERROR(IF(SUMPRODUCT(LARGE((Log!B5:B404="Yielding")*ROW(Log!B5:B404),10))=0,"",INDEX(Log!E:E,SUMPRODUCT(LARGE((Log!B5:B404="Yielding")*ROW(Log!B5:B404),10)))),"")} | F15: {=IFERROR(IF(SUMPRODUCT(LARGE((Log!B5:B404="Yielding")*ROW(Log!B5:B404),10))=0,"",INDEX(Log!F:F,SUMPRODUCT(LARGE((Log!B5:B404="Yielding")*ROW(Log!B5:B404),10)))),"")} | G15: {=IFERROR(IF(SUMPRODUCT(LARGE((Log!B5:B404="Yielding")*ROW(Log!B5:B404),10))=0,"",INDEX(Log!D:D,SUMPRODUCT(LARGE((Log!B5:B404="Yielding")*ROW(Log!B5:B404),10)))),"")}
A16: Notes on stats | D16: {=IFERROR(IF(SUMPRODUCT(LARGE((Log!B5:B404="Yielding")*ROW(Log!B5:B404),11))=0,"",INDEX(Log!A:A,SUMPRODUCT(LARGE((Log!B5:B404="Yielding")*ROW(Log!B5:B404),11)))),"")} | E16: {=IFERROR(IF(SUMPRODUCT(LARGE((Log!B5:B404="Yielding")*ROW(Log!B5:B404),11))=0,"",INDEX(Log!E:E,SUMPRODUCT(LARGE((Log!B5:B404="Yielding")*ROW(Log!B5:B404),11)))),"")} | F16: {=IFERROR(IF(SUMPRODUCT(LARGE((Log!B5:B404="Yielding")*ROW(Log!B5:B404),11))=0,"",INDEX(Log!F:F,SUMPRODUCT(LARGE((Log!B5:B404="Yielding")*ROW(Log!B5:B404),11)))),"")} | G16: {=IFERROR(IF(SUMPRODUCT(LARGE((Log!B5:B404="Yielding")*ROW(Log!B5:B404),11))=0,"",INDEX(Log!D:D,SUMPRODUCT(LARGE((Log!B5:B404="Yielding")*ROW(Log!B5:B404),11)))),"")}
A17: Benchmark = max load you held for 5s @9–9.5 on a yielding session. Only valid if Top Set Load is filled in Log. | D17: {=IFERROR(IF(SUMPRODUCT(LARGE((Log!B5:B404="Yielding")*ROW(Log!B5:B404),12))=0,"",INDEX(Log!A:A,SUMPRODUCT(LARGE((Log!B5:B404="Yielding")*ROW(Log!B5:B404),12)))),"")} | E17: {=IFERROR(IF(SUMPRODUCT(LARGE((Log!B5:B404="Yielding")*ROW(Log!B5:B404),12))=0,"",INDEX(Log!E:E,SUMPRODUCT(LARGE((Log!B5:B404="Yielding")*ROW(Log!B5:B404),12)))),"")} | F17: {=IFERROR(IF(SUMPRODUCT(LARGE((Log!B5:B404="Yielding")*ROW(Log!B5:B404),12))=0,"",INDEX(Log!F:F,SUMPRODUCT(LARGE((Log!B5:B404="Yielding")*ROW(Log!B5:B404),12)))),"")} | G17: {=IFERROR(IF(SUMPRODUCT(LARGE((Log!B5:B404="Yielding")*ROW(Log!B5:B404),12))=0,"",INDEX(Log!D:D,SUMPRODUCT(LARGE((Log!B5:B404="Yielding")*ROW(Log!B5:B404),12)))),"")}
D18: {=IFERROR(IF(SUMPRODUCT(LARGE((Log!B5:B404="Yielding")*ROW(Log!B5:B404),13))=0,"",INDEX(Log!A:A,SUMPRODUCT(LARGE((Log!B5:B404="Yielding")*ROW(Log!B5:B404),13)))),"")} | E18: {=IFERROR(IF(SUMPRODUCT(LARGE((Log!B5:B404="Yielding")*ROW(Log!B5:B404),13))=0,"",INDEX(Log!E:E,SUMPRODUCT(LARGE((Log!B5:B404="Yielding")*ROW(Log!B5:B404),13)))),"")} | F18: {=IFERROR(IF(SUMPRODUCT(LARGE((Log!B5:B404="Yielding")*ROW(Log!B5:B404),13))=0,"",INDEX(Log!F:F,SUMPRODUCT(LARGE((Log!B5:B404="Yielding")*ROW(Log!B5:B404),13)))),"")} | G18: {=IFERROR(IF(SUMPRODUCT(LARGE((Log!B5:B404="Yielding")*ROW(Log!B5:B404),13))=0,"",INDEX(Log!D:D,SUMPRODUCT(LARGE((Log!B5:B404="Yielding")*ROW(Log!B5:B404),13)))),"")}
D19: {=IFERROR(IF(SUMPRODUCT(LARGE((Log!B5:B404="Yielding")*ROW(Log!B5:B404),14))=0,"",INDEX(Log!A:A,SUMPRODUCT(LARGE((Log!B5:B404="Yielding")*ROW(Log!B5:B404),14)))),"")} | E19: {=IFERROR(IF(SUMPRODUCT(LARGE((Log!B5:B404="Yielding")*ROW(Log!B5:B404),14))=0,"",INDEX(Log!E:E,SUMPRODUCT(LARGE((Log!B5:B404="Yielding")*ROW(Log!B5:B404),14)))),"")} | F19: {=IFERROR(IF(SUMPRODUCT(LARGE((Log!B5:B404="Yielding")*ROW(Log!B5:B404),14))=0,"",INDEX(Log!F:F,SUMPRODUCT(LARGE((Log!B5:B404="Yielding")*ROW(Log!B5:B404),14)))),"")} | G19: {=IFERROR(IF(SUMPRODUCT(LARGE((Log!B5:B404="Yielding")*ROW(Log!B5:B404),14))=0,"",INDEX(Log!D:D,SUMPRODUCT(LARGE((Log!B5:B404="Yielding")*ROW(Log!B5:B404),14)))),"")}
D20: {=IFERROR(IF(SUMPRODUCT(LARGE((Log!B5:B404="Yielding")*ROW(Log!B5:B404),15))=0,"",INDEX(Log!A:A,SUMPRODUCT(LARGE((Log!B5:B404="Yielding")*ROW(Log!B5:B404),15)))),"")} | E20: {=IFERROR(IF(SUMPRODUCT(LARGE((Log!B5:B404="Yielding")*ROW(Log!B5:B404),15))=0,"",INDEX(Log!E:E,SUMPRODUCT(LARGE((Log!B5:B404="Yielding")*ROW(Log!B5:B404),15)))),"")} | F20: {=IFERROR(IF(SUMPRODUCT(LARGE((Log!B5:B404="Yielding")*ROW(Log!B5:B404),15))=0,"",INDEX(Log!F:F,SUMPRODUCT(LARGE((Log!B5:B404="Yielding")*ROW(Log!B5:B404),15)))),"")} | G20: {=IFERROR(IF(SUMPRODUCT(LARGE((Log!B5:B404="Yielding")*ROW(Log!B5:B404),15))=0,"",INDEX(Log!D:D,SUMPRODUCT(LARGE((Log!B5:B404="Yielding")*ROW(Log!B5:B404),15)))),"")}
D21: {=IFERROR(IF(SUMPRODUCT(LARGE((Log!B5:B404="Yielding")*ROW(Log!B5:B404),16))=0,"",INDEX(Log!A:A,SUMPRODUCT(LARGE((Log!B5:B404="Yielding")*ROW(Log!B5:B404),16)))),"")} | E21: {=IFERROR(IF(SUMPRODUCT(LARGE((Log!B5:B404="Yielding")*ROW(Log!B5:B404),16))=0,"",INDEX(Log!E:E,SUMPRODUCT(LARGE((Log!B5:B404="Yielding")*ROW(Log!B5:B404),16)))),"")} | F21: {=IFERROR(IF(SUMPRODUCT(LARGE((Log!B5:B404="Yielding")*ROW(Log!B5:B404),16))=0,"",INDEX(Log!F:F,SUMPRODUCT(LARGE((Log!B5:B404="Yielding")*ROW(Log!B5:B404),16)))),"")} | G21: {=IFERROR(IF(SUMPRODUCT(LARGE((Log!B5:B404="Yielding")*ROW(Log!B5:B404),16))=0,"",INDEX(Log!D:D,SUMPRODUCT(LARGE((Log!B5:B404="Yielding")*ROW(Log!B5:B404),16)))),"")}
D22: {=IFERROR(IF(SUMPRODUCT(LARGE((Log!B5:B404="Yielding")*ROW(Log!B5:B404),17))=0,"",INDEX(Log!A:A,SUMPRODUCT(LARGE((Log!B5:B404="Yielding")*ROW(Log!B5:B404),17)))),"")} | E22: {=IFERROR(IF(SUMPRODUCT(LARGE((Log!B5:B404="Yielding")*ROW(Log!B5:B404),17))=0,"",INDEX(Log!E:E,SUMPRODUCT(LARGE((Log!B5:B404="Yielding")*ROW(Log!B5:B404),17)))),"")} | F22: {=IFERROR(IF(SUMPRODUCT(LARGE((Log!B5:B404="Yielding")*ROW(Log!B5:B404),17))=0,"",INDEX(Log!F:F,SUMPRODUCT(LARGE((Log!B5:B404="Yielding")*ROW(Log!B5:B404),17)))),"")} | G22: {=IFERROR(IF(SUMPRODUCT(LARGE((Log!B5:B404="Yielding")*ROW(Log!B5:B404),17))=0,"",INDEX(Log!D:D,SUMPRODUCT(LARGE((Log!B5:B404="Yielding")*ROW(Log!B5:B404),17)))),"")}
D23: {=IFERROR(IF(SUMPRODUCT(LARGE((Log!B5:B404="Yielding")*ROW(Log!B5:B404),18))=0,"",INDEX(Log!A:A,SUMPRODUCT(LARGE((Log!B5:B404="Yielding")*ROW(Log!B5:B404),18)))),"")} | E23: {=IFERROR(IF(SUMPRODUCT(LARGE((Log!B5:B404="Yielding")*ROW(Log!B5:B404),18))=0,"",INDEX(Log!E:E,SUMPRODUCT(LARGE((Log!B5:B404="Yielding")*ROW(Log!B5:B404),18)))),"")} | F23: {=IFERROR(IF(SUMPRODUCT(LARGE((Log!B5:B404="Yielding")*ROW(Log!B5:B404),18))=0,"",INDEX(Log!F:F,SUMPRODUCT(LARGE((Log!B5:B404="Yielding")*ROW(Log!B5:B404),18)))),"")} | G23: {=IFERROR(IF(SUMPRODUCT(LARGE((Log!B5:B404="Yielding")*ROW(Log!B5:B404),18))=0,"",INDEX(Log!D:D,SUMPRODUCT(LARGE((Log!B5:B404="Yielding")*ROW(Log!B5:B404),18)))),"")}
D24: {=IFERROR(IF(SUMPRODUCT(LARGE((Log!B5:B404="Yielding")*ROW(Log!B5:B404),19))=0,"",INDEX(Log!A:A,SUMPRODUCT(LARGE((Log!B5:B404="Yielding")*ROW(Log!B5:B404),19)))),"")} | E24: {=IFERROR(IF(SUMPRODUCT(LARGE((Log!B5:B404="Yielding")*ROW(Log!B5:B404),19))=0,"",INDEX(Log!E:E,SUMPRODUCT(LARGE((Log!B5:B404="Yielding")*ROW(Log!B5:B404),19)))),"")} | F24: {=IFERROR(IF(SUMPRODUCT(LARGE((Log!B5:B404="Yielding")*ROW(Log!B5:B404),19))=0,"",INDEX(Log!F:F,SUMPRODUCT(LARGE((Log!B5:B404="Yielding")*ROW(Log!B5:B404),19)))),"")} | G24: {=IFERROR(IF(SUMPRODUCT(LARGE((Log!B5:B404="Yielding")*ROW(Log!B5:B404),19))=0,"",INDEX(Log!D:D,SUMPRODUCT(LARGE((Log!B5:B404="Yielding")*ROW(Log!B5:B404),19)))),"")}
D25: {=IFERROR(IF(SUMPRODUCT(LARGE((Log!B5:B404="Yielding")*ROW(Log!B5:B404),20))=0,"",INDEX(Log!A:A,SUMPRODUCT(LARGE((Log!B5:B404="Yielding")*ROW(Log!B5:B404),20)))),"")} | E25: {=IFERROR(IF(SUMPRODUCT(LARGE((Log!B5:B404="Yielding")*ROW(Log!B5:B404),20))=0,"",INDEX(Log!E:E,SUMPRODUCT(LARGE((Log!B5:B404="Yielding")*ROW(Log!B5:B404),20)))),"")} | F25: {=IFERROR(IF(SUMPRODUCT(LARGE((Log!B5:B404="Yielding")*ROW(Log!B5:B404),20))=0,"",INDEX(Log!F:F,SUMPRODUCT(LARGE((Log!B5:B404="Yielding")*ROW(Log!B5:B404),20)))),"")} | G25: {=IFERROR(IF(SUMPRODUCT(LARGE((Log!B5:B404="Yielding")*ROW(Log!B5:B404),20))=0,"",INDEX(Log!D:D,SUMPRODUCT(LARGE((Log!B5:B404="Yielding")*ROW(Log!B5:B404),20)))),"")}
D26: {=IFERROR(IF(SUMPRODUCT(LARGE((Log!B5:B404="Yielding")*ROW(Log!B5:B404),21))=0,"",INDEX(Log!A:A,SUMPRODUCT(LARGE((Log!B5:B404="Yielding")*ROW(Log!B5:B404),21)))),"")} | E26: {=IFERROR(IF(SUMPRODUCT(LARGE((Log!B5:B404="Yielding")*ROW(Log!B5:B404),21))=0,"",INDEX(Log!E:E,SUMPRODUCT(LARGE((Log!B5:B404="Yielding")*ROW(Log!B5:B404),21)))),"")} | F26: {=IFERROR(IF(SUMPRODUCT(LARGE((Log!B5:B404="Yielding")*ROW(Log!B5:B404),21))=0,"",INDEX(Log!F:F,SUMPRODUCT(LARGE((Log!B5:B404="Yielding")*ROW(Log!B5:B404),21)))),"")} | G26: {=IFERROR(IF(SUMPRODUCT(LARGE((Log!B5:B404="Yielding")*ROW(Log!B5:B404),21))=0,"",INDEX(Log!D:D,SUMPRODUCT(LARGE((Log!B5:B404="Yielding")*ROW(Log!B5:B404),21)))),"")}
D27: {=IFERROR(IF(SUMPRODUCT(LARGE((Log!B5:B404="Yielding")*ROW(Log!B5:B404),22))=0,"",INDEX(Log!A:A,SUMPRODUCT(LARGE((Log!B5:B404="Yielding")*ROW(Log!B5:B404),22)))),"")} | E27: {=IFERROR(IF(SUMPRODUCT(LARGE((Log!B5:B404="Yielding")*ROW(Log!B5:B404),22))=0,"",INDEX(Log!E:E,SUMPRODUCT(LARGE((Log!B5:B404="Yielding")*ROW(Log!B5:B404),22)))),"")} | F27: {=IFERROR(IF(SUMPRODUCT(LARGE((Log!B5:B404="Yielding")*ROW(Log!B5:B404),22))=0,"",INDEX(Log!F:F,SUMPRODUCT(LARGE((Log!B5:B404="Yielding")*ROW(Log!B5:B404),22)))),"")} | G27: {=IFERROR(IF(SUMPRODUCT(LARGE((Log!B5:B404="Yielding")*ROW(Log!B5:B404),22))=0,"",INDEX(Log!D:D,SUMPRODUCT(LARGE((Log!B5:B404="Yielding")*ROW(Log!B5:B404),22)))),"")}
D28: {=IFERROR(IF(SUMPRODUCT(LARGE((Log!B5:B404="Yielding")*ROW(Log!B5:B404),23))=0,"",INDEX(Log!A:A,SUMPRODUCT(LARGE((Log!B5:B404="Yielding")*ROW(Log!B5:B404),23)))),"")} | E28: {=IFERROR(IF(SUMPRODUCT(LARGE((Log!B5:B404="Yielding")*ROW(Log!B5:B404),23))=0,"",INDEX(Log!E:E,SUMPRODUCT(LARGE((Log!B5:B404="Yielding")*ROW(Log!B5:B404),23)))),"")} | F28: {=IFERROR(IF(SUMPRODUCT(LARGE((Log!B5:B404="Yielding")*ROW(Log!B5:B404),23))=0,"",INDEX(Log!F:F,SUMPRODUCT(LARGE((Log!B5:B404="Yielding")*ROW(Log!B5:B404),23)))),"")} | G28: {=IFERROR(IF(SUMPRODUCT(LARGE((Log!B5:B404="Yielding")*ROW(Log!B5:B404),23))=0,"",INDEX(Log!D:D,SUMPRODUCT(LARGE((Log!B5:B404="Yielding")*ROW(Log!B5:B404),23)))),"")}
D29: {=IFERROR(IF(SUMPRODUCT(LARGE((Log!B5:B404="Yielding")*ROW(Log!B5:B404),24))=0,"",INDEX(Log!A:A,SUMPRODUCT(LARGE((Log!B5:B404="Yielding")*ROW(Log!B5:B404),24)))),"")} | E29: {=IFERROR(IF(SUMPRODUCT(LARGE((Log!B5:B404="Yielding")*ROW(Log!B5:B404),24))=0,"",INDEX(Log!E:E,SUMPRODUCT(LARGE((Log!B5:B404="Yielding")*ROW(Log!B5:B404),24)))),"")} | F29: {=IFERROR(IF(SUMPRODUCT(LARGE((Log!B5:B404="Yielding")*ROW(Log!B5:B404),24))=0,"",INDEX(Log!F:F,SUMPRODUCT(LARGE((Log!B5:B404="Yielding")*ROW(Log!B5:B404),24)))),"")} | G29: {=IFERROR(IF(SUMPRODUCT(LARGE((Log!B5:B404="Yielding")*ROW(Log!B5:B404),24))=0,"",INDEX(Log!D:D,SUMPRODUCT(LARGE((Log!B5:B404="Yielding")*ROW(Log!B5:B404),24)))),"")}
D30: {=IFERROR(IF(SUMPRODUCT(LARGE((Log!B5:B404="Yielding")*ROW(Log!B5:B404),25))=0,"",INDEX(Log!A:A,SUMPRODUCT(LARGE((Log!B5:B404="Yielding")*ROW(Log!B5:B404),25)))),"")} | E30: {=IFERROR(IF(SUMPRODUCT(LARGE((Log!B5:B404="Yielding")*ROW(Log!B5:B404),25))=0,"",INDEX(Log!E:E,SUMPRODUCT(LARGE((Log!B5:B404="Yielding")*ROW(Log!B5:B404),25)))),"")} | F30: {=IFERROR(IF(SUMPRODUCT(LARGE((Log!B5:B404="Yielding")*ROW(Log!B5:B404),25))=0,"",INDEX(Log!F:F,SUMPRODUCT(LARGE((Log!B5:B404="Yielding")*ROW(Log!B5:B404),25)))),"")} | G30: {=IFERROR(IF(SUMPRODUCT(LARGE((Log!B5:B404="Yielding")*ROW(Log!B5:B404),25))=0,"",INDEX(Log!D:D,SUMPRODUCT(LARGE((Log!B5:B404="Yielding")*ROW(Log!B5:B404),25)))),"")}

Sheet Reference
A1: Reference
A2: Profile, schedule, autoregulation rules, block definitions, and exit criteria. Update profile stats as they change.
A4: Profile
A5: Bodyweight (kg) | B5: 67.5
A6: Height (cm) | B6: 172
A7: Outdoor bouldering | B7: 7B (V8)
A8: Moonboard | B8: 7A
A9: Kilter Board | B9: 7B
A10: Weighted pull-up 1RM | B10: +40 kg
A11: Current yielding benchmark | B11: +25 kg on 20mm half crimp, 5s (UPDATE after each benchmark test)
A12: Total load @ benchmark | B12: ~92.5 kg (~137% BW)
A13: Started hangboarding | B13: ~Dec 2025 (~5 months)
A14: Nutrition status | B14: Maintenance (cut complete)
A15: Long-term target
A17: Weekly Schedule
A18: Mon | B18: Rest (or easy climbing / no fingers)
A19: Tue | B19: OI primer + LIMIT BOARD (light neural prep, then board limit — not a heavy hang)
A20: Wed | B20: Rest or easy climbing — no max fingers
A21: Thu | B21: YIELDING — Volume day (4–5 sets @7–8, fixed sets, no extensions)
A22: Fri | B22: Rest or easy climbing — no max fingers
A23: Sat | B23: YIELDING — Heavy day (Sat). Trans I–II: 5s hangs, top set at block RPE, back-offs at @7–8. Peak (W11–14): 3s max singles @9.5, 3–5 efforts, 4–5 min rest, no back-offs.
A24: Sun | B24: Rest
A26: RPE Scale (for yielding top sets)
A27: RPE 10 | B27: Failure — fingers opened, could not hold full duration
A28: RPE 9.5
A29: RPE 9 | B29: Could have held ~1 more second
A30: RPE 8 | B30: Could have held ~2 more seconds (target for heavy day top set)
A31: RPE 7 | B31: Smooth, 3+ seconds left, no grip break sensation (target for volume day)
A32: RPE 6 | B32: Comfortable, clearly submaximal
A33: RPE 5 or lower | B33: Warmup territory
A35: Autoregulation Rules
A36: Pre-session readiness check | B36: During the 70%-benchmark warmup hang (5s), assess RPE. Normal feels @5–6. If @7+, drop today's loads 5–10% and skip fatigue extensions. If @8+ or any joint tenderness, skip session entirely.
A37: Tuesday top-set autoregulation | B37: Don't load based on last Tuesday's number. Load based on how 92% of last Tuesday's top set feels as a warmup-tier set today: @7 → today has +2.5–5 kg in it; @8 → match or +2.5 kg; @8.5+ → hold or back off.
A38: Fatigue stop (Tuesday back-offs) | B38: Start back-offs ~4–5 kg below top set (@7–8 genuinely). Continue back-off sets until ANY of: (1) cannot hit a full 5s at back-off load, (2) load must drop >5% to maintain @8, (3) grip break sensation appears before second 5 of the hold, (4) joint discomfort. Typical: 3–5 back-offs on good days, 1–2 when fatigued.
A39: Thursday volume rule | B39: Fixed 4–5 sets. NO extensions even if you feel good. If RPE on what should be @7–8 creeps to @8.5+ by set 3, drop load 5%. If still creeping, end at the set you're on. Thursday's job is buffer, not stimulus.
A40: Inter-week trend | B40: Log top set load, back-off count, and top set RPE every session. Two consecutive weeks of declining performance at same RPE = accumulated fatigue. Deload week 3 or 4 regardless of feel.
A41: Benchmark recalibration | B41: Every ~4 weeks, do a benchmark test: 1 set, 5s, find max load that hits @9–9.5. Recalibrate all working percentages from this number.
A43: Block Definitions (16-week cycle, Transmutation entry)
A44: Transmutation I (W1–4) | B44: Entry block. Tue @8.5–9 autoregulated top set + back-offs at 92–95% with fatigue stop. Thu 82–85% of Tue, 4–5 sets @7–8 (FIXED). Week 1 is a discovery check — see how the 48h between yielding sessions actually feels.
A45: Deload + Benchmark Test (W5) | B45: Tue: 3 sets at 75% benchmark @6–7. Sat: TEST 1 set max 5s @9–9.5. Update Reference benchmark with the result — Trans II percentages anchor here.
...

Sheet _Data
A1: # | B1: Date | C1: Day Role | D1: Top Load | E1: RPE | F1: E1RM | G1: Heavy E1RM | H1: Volume E1RM | I1: Working % of max E1RM | L1: # | M1: Date | N1: Next-Day Feel | O1: Rolling 5-avg | S1: Heavy % | T1: Volume %
A2: 1 | B2: {=IFERROR(IF(SUMPRODUCT(LARGE((Log!B5:B404="Yielding")*ROW(Log!B5:B404),1))=0,"",INDEX(Log!A:A,SUMPRODUCT(LARGE((Log!B5:B404="Yielding")*ROW(Log!B5:B404),1)))),"")} -> 46173 | C2: {=IFERROR(IF(SUMPRODUCT(LARGE((Log!B5:B404="Yielding")*ROW(Log!B5:B404),1))=0,"",INDEX(Log!D:D,SUMPRODUCT(LARGE((Log!B5:B404="Yielding")*ROW(Log!B5:B404),1)))),"")} -> Volume | D2: {=IFERROR(IF(SUMPRODUCT(LARGE((Log!B5:B404="Yielding")*ROW(Log!B5:B404),1))=0,"",INDEX(Log!E:E,SUMPRODUCT(LARGE((Log!B5:B404="Yielding")*ROW(Log!B5:B404),1)))),"")} -> 20 | E2: {=IFERROR(IF(SUMPRODUCT(LARGE((Log!B5:B404="Yielding")*ROW(Log!B5:B404),1))=0,"",INDEX(Log!F:F,SUMPRODUCT(LARGE((Log!B5:B404="Yielding")*ROW(Log!B5:B404),1)))),"")} -> 7 | F2: {=IFERROR(IF(SUMPRODUCT(LARGE((Log!B5:B404="Yielding")*ROW(Log!B5:B404),1))=0,"",INDEX(Log!M:M,SUMPRODUCT(LARGE((Log!B5:B404="Yielding")*ROW(Log!B5:B404),1)))),"")} -> 24.4 | G2: =IF(AND(ISNUMBER(F2),OR(C2="Heavy",C2="Test")),F2,"") | H2: =IF(AND(ISNUMBER(F2),C2="Volume"),F2,"") -> 24.4 | I2: =IFERROR(IF(F2="","",D2/MAX($F$2:$F$51)*100),"") -> 75.18797 | L2: 1 | M2: {=IFERROR(IF(SUMPRODUCT(LARGE((Log!J5:J404<>"")*ROW(Log!J5:J404),1))=0,"",INDEX(Log!A:A,SUMPRODUCT(LARGE((Log!J5:J404<>"")*ROW(Log!J5:J404),1)))),"")} -> 46173 | N2: {=IFERROR(IF(SUMPRODUCT(LARGE((Log!J5:J404<>"")*ROW(Log!J5:J404),1))=0,"",INDEX(Log!J:J,SUMPRODUCT(LARGE((Log!J5:J404<>"")*ROW(Log!J5:J404),1)))),"")} -> 3 | O2: =IFERROR(IF(COUNT(N2:N6)<3,"",AVERAGE(N2:N6)),"") -> 3.2 | S2: =IF(AND(ISNUMBER(I2),OR(C2="Heavy",C2="Test")),I2,"") | T2: =IF(AND(ISNUMBER(I2),C2="Volume"),I2,"") -> 75.18797
A3: 2 | B3: {=IFERROR(IF(SUMPRODUCT(LARGE((Log!B5:B404="Yielding")*ROW(Log!B5:B404),2))=0,"",INDEX(Log!A:A,SUMPRODUCT(LARGE((Log!B5:B404="Yielding")*ROW(Log!B5:B404),2)))),"")} -> 46168 | C3: {=IFERROR(IF(SUMPRODUCT(LARGE((Log!B5:B404="Yielding")*ROW(Log!B5:B404),2))=0,"",INDEX(Log!D:D,SUMPRODUCT(LARGE((Log!B5:B404="Yielding")*ROW(Log!B5:B404),2)))),"")} -> Heavy | D3: {=IFERROR(IF(SUMPRODUCT(LARGE((Log!B5:B404="Yielding")*ROW(Log!B5:B404),2))=0,"",INDEX(Log!E:E,SUMPRODUCT(LARGE((Log!B5:B404="Yielding")*ROW(Log!B5:B404),2)))),"")} -> 25 | E3: {=IFERROR(IF(SUMPRODUCT(LARGE((Log!B5:B404="Yielding")*ROW(Log!B5:B404),2))=0,"",INDEX(Log!F:F,SUMPRODUCT(LARGE((Log!B5:B404="Yielding")*ROW(Log!B5:B404),2)))),"")} -> 9 | F3: {=IFERROR(IF(SUMPRODUCT(LARGE((Log!B5:B404="Yielding")*ROW(Log!B5:B404),2))=0,"",INDEX(Log!M:M,SUMPRODUCT(LARGE((Log!B5:B404="Yielding")*ROW(Log!B5:B404),2)))),"")} -> 26.6 | G3: =IF(AND(ISNUMBER(F3),OR(C3="Heavy",C3="Test")),F3,"") -> 26.6 | H3: =IF(AND(ISNUMBER(F3),C3="Volume"),F3,"") | I3: =IFERROR(IF(F3="","",D3/MAX($F$2:$F$51)*100),"") -> 93.984962 | L3: 2 | M3: {=IFERROR(IF(SUMPRODUCT(LARGE((Log!J5:J404<>"")*ROW(Log!J5:J404),2))=0,"",INDEX(Log!A:A,SUMPRODUCT(LARGE((Log!J5:J404<>"")*ROW(Log!J5:J404),2)))),"")} -> 46170 | N3: {=IFERROR(IF(SUMPRODUCT(LARGE((Log!J5:J404<>"")*ROW(Log!J5:J404),2))=0,"",INDEX(Log!J:J,SUMPRODUCT(LARGE((Log!J5:J404<>"")*ROW(Log!J5:J404),2)))),"")} -> 3 | O3: =IFERROR(IF(COUNT(N3:N7)<3,"",AVERAGE(N3:N7)),"") -> 3.2 | S3: =IF(AND(ISNUMBER(I3),OR(C3="Heavy",C3="Test")),I3,"") -> 93.984962 | T3: =IF(AND(ISNUMBER(I3),C3="Volume"),I3,"")
A4: 3 | B4: {=IFERROR(IF(SUMPRODUCT(LARGE((Log!B5:B404="Yielding")*ROW(Log!B5:B404),3))=0,"",INDEX(Log!A:A,SUMPRODUCT(LARGE((Log!B5:B404="Yielding")*ROW(Log!B5:B404),3)))),"")} -> 46161 | C4: {=IFERROR(IF(SUMPRODUCT(LARGE((Log!B5:B404="Yielding")*ROW(Log!B5:B404),3))=0,"",INDEX(Log!D:D,SUMPRODUCT(LARGE((Log!B5:B404="Yielding")*ROW(Log!B5:B404),3)))),"")} -> Heavy | D4: {=IFERROR(IF(SUMPRODUCT(LARGE((Log!B5:B404="Yielding")*ROW(Log!B5:B404),3))=0,"",INDEX(Log!E:E,SUMPRODUCT(LARGE((Log!B5:B404="Yielding")*ROW(Log!B5:B404),3)))),"")} -> 25 | E4: {=IFERROR(IF(SUMPRODUCT(LARGE((Log!B5:B404="Yielding")*ROW(Log!B5:B404),3))=0,"",INDEX(Log!F:F,SUMPRODUCT(LARGE((Log!B5:B404="Yielding")*ROW(Log!B5:B404),3)))),"")} -> 10 | F4: {=IFERROR(IF(SUMPRODUCT(LARGE((Log!B5:B404="Yielding")*ROW(Log!B5:B404),3))=0,"",INDEX(Log!M:M,SUMPRODUCT(LARGE((Log!B5:B404="Yielding")*ROW(Log!B5:B404),3)))),"")} -> 25 | G4: =IF(AND(ISNUMBER(F4),OR(C4="Heavy",C4="Test")),F4,"") -> 25 | H4: =IF(AND(ISNUMBER(F4),C4="Volume"),F4,"") | I4: =IFERROR(IF(F4="","",D4/MAX($F$2:$F$51)*100),"") -> 93.984962 | L4: 3 | M4: {=IFERROR(IF(SUMPRODUCT(LARGE((Log!J5:J404<>"")*ROW(Log!J5:J404),3))=0,"",INDEX(Log!A:A,SUMPRODUCT(LARGE((Log!J5:J404<>"")*ROW(Log!J5:J404),3)))),"")} -> 46168 | N4: {=IFERROR(IF(SUMPRODUCT(LARGE((Log!J5:J404<>"")*ROW(Log!J5:J404),3))=0,"",INDEX(Log!J:J,SUMPRODUCT(LARGE((Log!J5:J404<>"")*ROW(Log!J5:J404),3)))),"")} -> 4 | O4: =IFERROR(IF(COUNT(N4:N8)<3,"",AVERAGE(N4:N8)),"") -> 3.4 | S4: =IF(AND(ISNUMBER(I4),OR(C4="Heavy",C4="Test")),I4,"") -> 93.984962 | T4: =IF(AND(ISNUMBER(I4),C4="Volume"),I4,"")
